<?xml version="1.0" encoding="UTF-8"?>
<testng-results ignored="0" total="1" passed="0" failed="1" skipped="0">
  <reporter-output>
  </reporter-output>
  <suite started-at="2023-06-12T14:23:46Z" name="netbankV1" finished-at="2023-06-12T14:24:16Z" duration-ms="29462">
    <groups>
    </groups>
    <test started-at="2023-06-12T14:23:46Z" name="NetBanking App Test" finished-at="2023-06-12T14:24:16Z" duration-ms="29462">
      <class name="com.netbankV1.testCases.TC_AddCustomer_003">
        <test-method is-config="true" signature="setup(java.lang.String)[pri:0, instance:com.netbankV1.testCases.TC_AddCustomer_003@670002]" started-at="2023-06-12T14:23:47Z" name="setup" finished-at="2023-06-12T14:23:58Z" duration-ms="11120" status="PASS">
          <params>
            <param index="0">
              <value>
                <![CDATA[chrome]]>
              </value>
            </param>
          </params>
          <reporter-output>
          </reporter-output>
        </test-method> <!-- setup -->
        <test-method signature="addNewCustomer()[pri:0, instance:com.netbankV1.testCases.TC_AddCustomer_003@670002]" started-at="2023-06-12T14:23:58Z" name="addNewCustomer" finished-at="2023-06-12T14:24:15Z" duration-ms="17353" status="FAIL">
          <exception class="java.lang.AssertionError">
            <message>
              <![CDATA[expected [true] but found [false]]]>
            </message>
            <full-stacktrace>
              <![CDATA[java.lang.AssertionError: expected [true] but found [false]
at org.testng.Assert.fail(Assert.java:96)
at org.testng.Assert.failNotEquals(Assert.java:776)
at org.testng.Assert.assertTrue(Assert.java:44)
at org.testng.Assert.assertTrue(Assert.java:54)
at com.netbankV1.testCases.TC_AddCustomer_003.addNewCustomer(TC_AddCustomer_003.java:66)
at java.base/jdk.internal.reflect.DirectMethodHandleAccessor.invoke(DirectMethodHandleAccessor.java:104)
at java.base/java.lang.reflect.Method.invoke(Method.java:578)
at org.testng.internal.MethodInvocationHelper.invokeMethod(MethodInvocationHelper.java:124)
at org.testng.internal.Invoker.invokeMethod(Invoker.java:583)
at org.testng.internal.Invoker.invokeTestMethod(Invoker.java:719)
at org.testng.internal.Invoker.invokeTestMethods(Invoker.java:989)
at org.testng.internal.TestMethodWorker.invokeTestMethods(TestMethodWorker.java:125)
at org.testng.internal.TestMethodWorker.run(TestMethodWorker.java:109)
at org.testng.TestRunner.privateRun(TestRunner.java:648)
at org.testng.TestRunner.run(TestRunner.java:505)
at org.testng.SuiteRunner.runTest(SuiteRunner.java:455)
at org.testng.SuiteRunner.runSequentially(SuiteRunner.java:450)
at org.testng.SuiteRunner.privateRun(SuiteRunner.java:415)
at org.testng.SuiteRunner.run(SuiteRunner.java:364)
at org.testng.SuiteRunnerWorker.runSuite(SuiteRunnerWorker.java:52)
at org.testng.SuiteRunnerWorker.run(SuiteRunnerWorker.java:84)
at org.testng.TestNG.runSuitesSequentially(TestNG.java:1208)
at org.testng.TestNG.runSuitesLocally(TestNG.java:1137)
at org.testng.TestNG.runSuites(TestNG.java:1049)
at org.testng.TestNG.run(TestNG.java:1017)
at org.testng.remote.AbstractRemoteTestNG.run(AbstractRemoteTestNG.java:115)
at org.testng.remote.RemoteTestNG.initAndRun(RemoteTestNG.java:251)
at org.testng.remote.RemoteTestNG.main(RemoteTestNG.java:77)
]]>
            </full-stacktrace>
          </exception> <!-- java.lang.AssertionError -->
          <reporter-output>
          </reporter-output>
        </test-method> <!-- addNewCustomer -->
        <test-method is-config="true" signature="tearDown()[pri:0, instance:com.netbankV1.testCases.TC_AddCustomer_003@670002]" started-at="2023-06-12T14:24:15Z" name="tearDown" finished-at="2023-06-12T14:24:16Z" duration-ms="501" status="PASS">
          <reporter-output>
          </reporter-output>
        </test-method> <!-- tearDown -->
      </class> <!-- com.netbankV1.testCases.TC_AddCustomer_003 -->
    </test> <!-- NetBanking App Test -->
  </suite> <!-- netbankV1 -->
</testng-results>
